Warning: no access to tty (Bad file descriptor).
Thus no job control in this shell.
basename: missing operand
Try 'basename --help' for more information.
Your Python environment has been changed to the 'virenvConda' conda environment. Here's the active version of Python:
/scratch/ehsanm/virtualEnv//virenvConda/bin/python
Python 3.7.3
To switch back to your default Python environment, type 'source deactivate.csh'
Currently Loaded Modulefiles:
  1) intel/2015
cputime      unlimited
filesize     unlimited
datasize     unlimited
stacksize    unlimited
coredumpsize unlimited
memoryuse    unlimited
vmemoryuse   unlimited
descriptors  4096 
memorylocked unlimited
maxproc      256780 
maxlocks     unlimited
maxsignal    256780 
maxmessage   819200 
maxnice      0 
maxrtprio    0 
maxrttime    unlimited
 job s4sep =====> submitted
Mon Jul  8 02:28:19 EDT 2019
Traceback (most recent call last):
  File "../run_scripts/spatial_CMAQ_analysis_for_cluster.py", line 1407, in <module>
    main()
  File "../run_scripts/spatial_CMAQ_analysis_for_cluster.py", line 336, in main
    pmdiag_open_scen = Dataset( pmdiag_input_scen , 'r' )
  File "netCDF4/_netCDF4.pyx", line 2291, in netCDF4._netCDF4.Dataset.__init__
  File "netCDF4/_netCDF4.pyx", line 1855, in netCDF4._netCDF4._ensure_nc_success
FileNotFoundError: [Errno 2] No such file or directory: b'/storage/ehsanm/USFS_CA_WRF_1km_project/data_analysis/cmaq_data/scen_4/CCTM_PMDIAG_v52_CA_WRF_1km_griddedAgBioNonptPtfire_scen4_mpi_standard_20160901.nc'
 job s4sep =====> ended
Mon Jul  8 02:28:41 EDT 2019
Warning: no access to tty (Bad file descriptor).
Thus no job control in this shell.
basename: missing operand
Try 'basename --help' for more information.
Your Python environment has been changed to the 'virenvConda' conda environment. Here's the active version of Python:
/scratch/ehsanm/virtualEnv//virenvConda/bin/python
Python 3.7.3
To switch back to your default Python environment, type 'source deactivate.csh'
Currently Loaded Modulefiles:
  1) intel/2015
cputime      unlimited
filesize     unlimited
datasize     unlimited
stacksize    unlimited
coredumpsize unlimited
memoryuse    unlimited
vmemoryuse   unlimited
descriptors  4096 
memorylocked unlimited
maxproc      256780 
maxlocks     unlimited
maxsignal    256780 
maxmessage   819200 
maxnice      0 
maxrtprio    0 
maxrttime    unlimited
 job s4sep =====> submitted
Mon Jul  8 21:00:35 EDT 2019
Traceback (most recent call last):
  File "../run_scripts/spatial_CMAQ_analysis_for_cluster.py", line 1407, in <module>
    main()
  File "../run_scripts/spatial_CMAQ_analysis_for_cluster.py", line 639, in main
    plt.plot( x_ , y_ )
  File "/scratch/ehsanm/virtualEnv/virenvConda/lib/python3.7/site-packages/matplotlib/pyplot.py", line 2787, in plot
    return gca().plot(
  File "/scratch/ehsanm/virtualEnv/virenvConda/lib/python3.7/site-packages/matplotlib/pyplot.py", line 920, in gca
    return gcf().gca(**kwargs)
  File "/scratch/ehsanm/virtualEnv/virenvConda/lib/python3.7/site-packages/matplotlib/pyplot.py", line 597, in gcf
    return figure()
  File "/scratch/ehsanm/virtualEnv/virenvConda/lib/python3.7/site-packages/matplotlib/pyplot.py", line 539, in figure
    **kwargs)
  File "/scratch/ehsanm/virtualEnv/virenvConda/lib/python3.7/site-packages/matplotlib/backend_bases.py", line 3252, in new_figure_manager
    return cls.new_figure_manager_given_figure(num, fig)
  File "/scratch/ehsanm/virtualEnv/virenvConda/lib/python3.7/site-packages/matplotlib/backends/_backend_tk.py", line 946, in new_figure_manager_given_figure
    window = tk.Tk(className="matplotlib")
  File "/scratch/ehsanm/virtualEnv/virenvConda/lib/python3.7/tkinter/__init__.py", line 2023, in __init__
    self.tk = _tkinter.create(screenName, baseName, className, interactive, wantobjects, useTk, sync, use)
_tkinter.TclError: couldn't connect to display "localhost:11.0"
 job s4sep =====> ended
Mon Jul  8 21:25:40 EDT 2019
Warning: no access to tty (Bad file descriptor).
Thus no job control in this shell.
basename: missing operand
Try 'basename --help' for more information.
Your Python environment has been changed to the 'virenvConda' conda environment. Here's the active version of Python:
/scratch/ehsanm/virtualEnv//virenvConda/bin/python
Python 3.7.3
To switch back to your default Python environment, type 'source deactivate.csh'
Currently Loaded Modulefiles:
  1) intel/2015
cputime      unlimited
filesize     unlimited
datasize     unlimited
stacksize    unlimited
coredumpsize unlimited
memoryuse    unlimited
vmemoryuse   unlimited
descriptors  4096 
memorylocked unlimited
maxproc      256780 
maxlocks     unlimited
maxsignal    256780 
maxmessage   819200 
maxnice      0 
maxrtprio    0 
maxrttime    unlimited
 job s4sep =====> submitted
Mon Jul  8 21:52:50 EDT 2019
Traceback (most recent call last):
  File "../run_scripts/spatial_CMAQ_analysis_for_cluster.py", line 1407, in <module>
    main()
  File "../run_scripts/spatial_CMAQ_analysis_for_cluster.py", line 639, in main
    plt.plot( x_ , y_ )
  File "/scratch/ehsanm/virtualEnv/virenvConda/lib/python3.7/site-packages/matplotlib/pyplot.py", line 2787, in plot
    return gca().plot(
  File "/scratch/ehsanm/virtualEnv/virenvConda/lib/python3.7/site-packages/matplotlib/pyplot.py", line 920, in gca
    return gcf().gca(**kwargs)
  File "/scratch/ehsanm/virtualEnv/virenvConda/lib/python3.7/site-packages/matplotlib/pyplot.py", line 597, in gcf
    return figure()
  File "/scratch/ehsanm/virtualEnv/virenvConda/lib/python3.7/site-packages/matplotlib/pyplot.py", line 539, in figure
    **kwargs)
  File "/scratch/ehsanm/virtualEnv/virenvConda/lib/python3.7/site-packages/matplotlib/backend_bases.py", line 3252, in new_figure_manager
    return cls.new_figure_manager_given_figure(num, fig)
  File "/scratch/ehsanm/virtualEnv/virenvConda/lib/python3.7/site-packages/matplotlib/backends/_backend_tk.py", line 946, in new_figure_manager_given_figure
    window = tk.Tk(className="matplotlib")
  File "/scratch/ehsanm/virtualEnv/virenvConda/lib/python3.7/tkinter/__init__.py", line 2023, in __init__
    self.tk = _tkinter.create(screenName, baseName, className, interactive, wantobjects, useTk, sync, use)
_tkinter.TclError: couldn't connect to display "localhost:11.0"
 job s4sep =====> ended
Mon Jul  8 22:17:50 EDT 2019
Warning: no access to tty (Bad file descriptor).
Thus no job control in this shell.
basename: missing operand
Try 'basename --help' for more information.
Your Python environment has been changed to the 'virenvConda' conda environment. Here's the active version of Python:
/scratch/ehsanm/virtualEnv//virenvConda/bin/python
Python 3.7.3
To switch back to your default Python environment, type 'source deactivate.csh'
Currently Loaded Modulefiles:
  1) intel/2015
cputime      unlimited
filesize     unlimited
datasize     unlimited
stacksize    unlimited
coredumpsize unlimited
memoryuse    unlimited
vmemoryuse   unlimited
descriptors  4096 
memorylocked unlimited
maxproc      256780 
maxlocks     unlimited
maxsignal    256780 
maxmessage   819200 
maxnice      0 
maxrtprio    0 
maxrttime    unlimited
 job s4sep =====> submitted
Mon Jul  8 22:58:48 EDT 2019
Traceback (most recent call last):
  File "../run_scripts/spatial_CMAQ_analysis_for_cluster.py", line 1407, in <module>
    main()
  File "../run_scripts/spatial_CMAQ_analysis_for_cluster.py", line 639, in main
    plt.plot( x_ , y_ )
  File "/scratch/ehsanm/virtualEnv/virenvConda/lib/python3.7/site-packages/matplotlib/pyplot.py", line 2787, in plot
    return gca().plot(
  File "/scratch/ehsanm/virtualEnv/virenvConda/lib/python3.7/site-packages/matplotlib/pyplot.py", line 920, in gca
    return gcf().gca(**kwargs)
  File "/scratch/ehsanm/virtualEnv/virenvConda/lib/python3.7/site-packages/matplotlib/pyplot.py", line 597, in gcf
    return figure()
  File "/scratch/ehsanm/virtualEnv/virenvConda/lib/python3.7/site-packages/matplotlib/pyplot.py", line 539, in figure
    **kwargs)
  File "/scratch/ehsanm/virtualEnv/virenvConda/lib/python3.7/site-packages/matplotlib/backend_bases.py", line 3252, in new_figure_manager
    return cls.new_figure_manager_given_figure(num, fig)
  File "/scratch/ehsanm/virtualEnv/virenvConda/lib/python3.7/site-packages/matplotlib/backends/_backend_tk.py", line 946, in new_figure_manager_given_figure
    window = tk.Tk(className="matplotlib")
  File "/scratch/ehsanm/virtualEnv/virenvConda/lib/python3.7/tkinter/__init__.py", line 2023, in __init__
    self.tk = _tkinter.create(screenName, baseName, className, interactive, wantobjects, useTk, sync, use)
_tkinter.TclError: couldn't connect to display "localhost:11.0"
 job s4sep =====> ended
Mon Jul  8 23:22:18 EDT 2019
Warning: no access to tty (Bad file descriptor).
Thus no job control in this shell.
basename: missing operand
Try 'basename --help' for more information.
Your Python environment has been changed to the 'virenvConda' conda environment. Here's the active version of Python:
/scratch/ehsanm/virtualEnv//virenvConda/bin/python
Python 3.7.3
To switch back to your default Python environment, type 'source deactivate.csh'
Currently Loaded Modulefiles:
  1) intel/2015
cputime      unlimited
filesize     unlimited
datasize     unlimited
stacksize    unlimited
coredumpsize unlimited
memoryuse    unlimited
vmemoryuse   unlimited
descriptors  4096 
memorylocked unlimited
maxproc      256780 
maxlocks     unlimited
maxsignal    256780 
maxmessage   819200 
maxnice      0 
maxrtprio    0 
maxrttime    unlimited
 job s4sep =====> submitted
Tue Jul  9 00:01:35 EDT 2019
Traceback (most recent call last):
  File "../run_scripts/spatial_CMAQ_analysis_for_cluster.py", line 1407, in <module>
    main()
  File "../run_scripts/spatial_CMAQ_analysis_for_cluster.py", line 639, in main
    plt.plot( x_ , y_ )
  File "/scratch/ehsanm/virtualEnv/virenvConda/lib/python3.7/site-packages/matplotlib/pyplot.py", line 2787, in plot
    return gca().plot(
  File "/scratch/ehsanm/virtualEnv/virenvConda/lib/python3.7/site-packages/matplotlib/pyplot.py", line 920, in gca
    return gcf().gca(**kwargs)
  File "/scratch/ehsanm/virtualEnv/virenvConda/lib/python3.7/site-packages/matplotlib/pyplot.py", line 597, in gcf
    return figure()
  File "/scratch/ehsanm/virtualEnv/virenvConda/lib/python3.7/site-packages/matplotlib/pyplot.py", line 539, in figure
    **kwargs)
  File "/scratch/ehsanm/virtualEnv/virenvConda/lib/python3.7/site-packages/matplotlib/backend_bases.py", line 3252, in new_figure_manager
    return cls.new_figure_manager_given_figure(num, fig)
  File "/scratch/ehsanm/virtualEnv/virenvConda/lib/python3.7/site-packages/matplotlib/backends/_backend_tk.py", line 946, in new_figure_manager_given_figure
    window = tk.Tk(className="matplotlib")
  File "/scratch/ehsanm/virtualEnv/virenvConda/lib/python3.7/tkinter/__init__.py", line 2023, in __init__
    self.tk = _tkinter.create(screenName, baseName, className, interactive, wantobjects, useTk, sync, use)
_tkinter.TclError: couldn't connect to display "localhost:11.0"
 job s4sep =====> ended
Tue Jul  9 00:26:55 EDT 2019
Warning: no access to tty (Bad file descriptor).
Thus no job control in this shell.
basename: missing operand
Try 'basename --help' for more information.
Your Python environment has been changed to the 'virenvConda' conda environment. Here's the active version of Python:
/scratch/ehsanm/virtualEnv//virenvConda/bin/python
Python 3.7.3
To switch back to your default Python environment, type 'source deactivate.csh'
Currently Loaded Modulefiles:
  1) intel/2015
cputime      unlimited
filesize     unlimited
datasize     unlimited
stacksize    unlimited
coredumpsize unlimited
memoryuse    unlimited
vmemoryuse   unlimited
descriptors  4096 
memorylocked unlimited
maxproc      256780 
maxlocks     unlimited
maxsignal    256780 
maxmessage   819200 
maxnice      0 
maxrtprio    0 
maxrttime    unlimited
 job s4sep =====> submitted
Tue Jul  9 00:55:48 EDT 2019
Traceback (most recent call last):
  File "../run_scripts/spatial_CMAQ_analysis_for_cluster.py", line 1407, in <module>
    main()
  File "../run_scripts/spatial_CMAQ_analysis_for_cluster.py", line 639, in main
    plt.plot( x_ , y_ )
  File "/scratch/ehsanm/virtualEnv/virenvConda/lib/python3.7/site-packages/matplotlib/pyplot.py", line 2787, in plot
    return gca().plot(
  File "/scratch/ehsanm/virtualEnv/virenvConda/lib/python3.7/site-packages/matplotlib/pyplot.py", line 920, in gca
    return gcf().gca(**kwargs)
  File "/scratch/ehsanm/virtualEnv/virenvConda/lib/python3.7/site-packages/matplotlib/pyplot.py", line 597, in gcf
    return figure()
  File "/scratch/ehsanm/virtualEnv/virenvConda/lib/python3.7/site-packages/matplotlib/pyplot.py", line 539, in figure
    **kwargs)
  File "/scratch/ehsanm/virtualEnv/virenvConda/lib/python3.7/site-packages/matplotlib/backend_bases.py", line 3252, in new_figure_manager
    return cls.new_figure_manager_given_figure(num, fig)
  File "/scratch/ehsanm/virtualEnv/virenvConda/lib/python3.7/site-packages/matplotlib/backends/_backend_tk.py", line 946, in new_figure_manager_given_figure
    window = tk.Tk(className="matplotlib")
  File "/scratch/ehsanm/virtualEnv/virenvConda/lib/python3.7/tkinter/__init__.py", line 2023, in __init__
    self.tk = _tkinter.create(screenName, baseName, className, interactive, wantobjects, useTk, sync, use)
_tkinter.TclError: couldn't connect to display "localhost:11.0"
 job s4sep =====> ended
Tue Jul  9 01:21:10 EDT 2019
Warning: no access to tty (Bad file descriptor).
Thus no job control in this shell.
basename: missing operand
Try 'basename --help' for more information.
Your Python environment has been changed to the 'virenvConda' conda environment. Here's the active version of Python:
/scratch/ehsanm/virtualEnv//virenvConda/bin/python
Python 3.7.3
To switch back to your default Python environment, type 'source deactivate.csh'
Currently Loaded Modulefiles:
  1) intel/2015
cputime      unlimited
filesize     unlimited
datasize     unlimited
stacksize    unlimited
coredumpsize unlimited
memoryuse    unlimited
vmemoryuse   unlimited
descriptors  4096 
memorylocked unlimited
maxproc      256780 
maxlocks     unlimited
maxsignal    256780 
maxmessage   819200 
maxnice      0 
maxrtprio    0 
maxrttime    unlimited
 job s4sep =====> submitted
Tue Jul  9 01:47:19 EDT 2019
Traceback (most recent call last):
  File "../run_scripts/spatial_CMAQ_analysis_for_cluster.py", line 1407, in <module>
    main()
  File "../run_scripts/spatial_CMAQ_analysis_for_cluster.py", line 639, in main
    plt.plot( x_ , y_ )
  File "/scratch/ehsanm/virtualEnv/virenvConda/lib/python3.7/site-packages/matplotlib/pyplot.py", line 2787, in plot
    return gca().plot(
  File "/scratch/ehsanm/virtualEnv/virenvConda/lib/python3.7/site-packages/matplotlib/pyplot.py", line 920, in gca
    return gcf().gca(**kwargs)
  File "/scratch/ehsanm/virtualEnv/virenvConda/lib/python3.7/site-packages/matplotlib/pyplot.py", line 597, in gcf
    return figure()
  File "/scratch/ehsanm/virtualEnv/virenvConda/lib/python3.7/site-packages/matplotlib/pyplot.py", line 539, in figure
    **kwargs)
  File "/scratch/ehsanm/virtualEnv/virenvConda/lib/python3.7/site-packages/matplotlib/backend_bases.py", line 3252, in new_figure_manager
    return cls.new_figure_manager_given_figure(num, fig)
  File "/scratch/ehsanm/virtualEnv/virenvConda/lib/python3.7/site-packages/matplotlib/backends/_backend_tk.py", line 946, in new_figure_manager_given_figure
    window = tk.Tk(className="matplotlib")
  File "/scratch/ehsanm/virtualEnv/virenvConda/lib/python3.7/tkinter/__init__.py", line 2023, in __init__
    self.tk = _tkinter.create(screenName, baseName, className, interactive, wantobjects, useTk, sync, use)
_tkinter.TclError: couldn't connect to display "localhost:11.0"
 job s4sep =====> ended
Tue Jul  9 02:12:50 EDT 2019
